Workbook

Sheet Dashboard
A1: Society Maintenance & Expense Dashboard
A4: Total Collection | C4: Total Expenses | E4: Net Balance | G4: Collection %
A5: ='Maintenance Detail'!E46 | C5: =Expenses!D7 | E5: =A5-C5 | G5: =COUNTIF('Maintenance Detail'!I3:I45, "Paid")/COUNTA('Maintenance Detail'!I3:I45)
A9: Collection Summary | D9: Unit Type Summary | G9: Payment Mode Summary
A10: Status | B10: Count | D10: Type | E10: Amount | G10: Mode | H10: Amount
A11: Paid | B11: =COUNTIF('Maintenance Detail'!I3:I45, "Paid") | D11: Shops | E11: =SUMIF('Maintenance Detail'!D3:D45, "*Shop*", 'Maintenance Detail'!E3:E45) | G11: Online | H11: =SUMIF('Maintenance Detail'!F3:F45, "Online", 'Maintenance Detail'!E3:E45)
A12: Pending | B12: =COUNTIF('Maintenance Detail'!I3:I45, "Pending") | D12: Flats | E12: =SUMIF('Maintenance Detail'!D3:D45, "*Flat*", 'Maintenance Detail'!E3:E45) | G12: Cash | H12: =SUMIF('Maintenance Detail'!F3:F45, "Cash", 'Maintenance Detail'!E3:E45)
A15: Defaulters / Pending List
A16: Flat/Shop No. | B16: Owner Name
A17: ='Maintenance Detail'!D5 | B17: ='Maintenance Detail'!B5
A18: ='Maintenance Detail'!D6 | B18: ='Maintenance Detail'!B6
A19: ='Maintenance Detail'!D7 | B19: ='Maintenance Detail'!B7
A20: ='Maintenance Detail'!D13 | B20: ='Maintenance Detail'!B13
A21: ='Maintenance Detail'!D15 | B21: ='Maintenance Detail'!B15
A22: ='Maintenance Detail'!D19 | B22: ='Maintenance Detail'!B19
A23: ='Maintenance Detail'!D25 | B23: ='Maintenance Detail'!B25
A24: ='Maintenance Detail'!D26 | B24: ='Maintenance Detail'!B26
A25: ='Maintenance Detail'!D33 | B25: ='Maintenance Detail'!B33
A26: ='Maintenance Detail'!D35 | B26: ='Maintenance Detail'!B35
A27: ='Maintenance Detail'!D40 | B27: ='Maintenance Detail'!B40
A28: ='Maintenance Detail'!D42 | B28: ='Maintenance Detail'!B42

Sheet Maintenance Detail
A2: Sr. No. | B2: Owner Name | C2: Mobile Number | D2: Flat/Shop No. | E2: Maintenance Amount | F2: Payment Mode | G2: Payment Date | H2: Receiver's Name | I2: Status
A3: 1 | B3: Reshma Tailor | D3: Shop no. 1 | E3: 500 | F3: Online | G3: 09 July 2026 | H3: Vivek | I3: =IF(E3>0, "Paid", "Pending")
A4: 2 | B4: Kadam Chai | D4: Shop no. 2 | E4: 500 | F4: Online | G4: 09 July 2026 | H4: Vivek | I4: =IF(E4>0, "Paid", "Pending")
A5: 3 | B5: Chicken Shop | D5: Shop no. 3 | E5: 0 | H5: Vivek | I5: =IF(E5>0, "Paid", "Pending")
A6: 4 | B6: Dev Narayan Dairy | D6: Shop no. 4 | E6: 0 | H6: Vivek | I6: =IF(E6>0, "Paid", "Pending")
A7: 5 | B7: Beauty Parlour | D7: Shop no. 5 | E7: 0 | H7: Vivek | I7: =IF(E7>0, "Paid", "Pending")
A8: 6 | B8: Salon | D8: Shop no. 6 | E8: 500 | F8: Online | G8: 09 July 2026 | H8: Vivek | I8: =IF(E8>0, "Paid", "Pending")
A9: 7 | B9: Bhajiwala | D9: Shop no. 7 | E9: 500 | F9: Cash | G9: 09 July 2026 | H9: Vivek | I9: =IF(E9>0, "Paid", "Pending")
A10: 8 | B10: Mhatre | D10: Ground floor | E10: 700 | F10: Cash | G10: 09 July 2026 | H10: Vivek | I10: =IF(E10>0, "Paid", "Pending")
A11: 9 | D11: Flat no 101 | E11: 700 | F11: Cash | G11: 09 July 2026 | H11: Vivek | I11: =IF(E11>0, "Paid", "Pending")
A12: 10 | D12: Flat no 102 | E12: 700 | F12: Cash | G12: 09 July 2026 | H12: Vivek | I12: =IF(E12>0, "Paid", "Pending")
A13: 11 | B13: Ramchandra Pal | D13: Flat no 103 | E13: 0 | H13: Vivek | I13: =IF(E13>0, "Paid", "Pending")
A14: 12 | B14: Ashish ghrat | D14: Flat no 104 | E14: 700 | F14: Online | H14: Vivek | I14: =IF(E14>0, "Paid", "Pending")
A15: 13 | B15: Shrivas Prajapati | D15: Flat no 105 | E15: 0 | H15: Vivek | I15: =IF(E15>0, "Paid", "Pending")
A16: 14 | B16: Mhatre | D16: Flat no 106 | E16: 700 | F16: Cash | G16: 09 July 2026 | H16: Vivek | I16: =IF(E16>0, "Paid", "Pending")
A17: 15 | B17: Harishchandra Patil | D17: Flat no 107 | E17: 700 | F17: Online | G17: 09 July 2026 | H17: Vivek | I17: =IF(E17>0, "Paid", "Pending")
A18: 16 | B18: Devendra Bhilare | D18: Flat no 201 | E18: 700 | F18: Cash | G18: 13 July 2026 | H18: Vivek | I18: =IF(E18>0, "Paid", "Pending")
A19: 17 | B19: Suresh Ovala | D19: Flat no 202 | E19: 0 | H19: Vivek | I19: =IF(E19>0, "Paid", "Pending")
A20: 18 | B20: Mohan Singh | D20: Flat no 203 | E20: 700 | F20: Online | G20: 09 July 2026 | H20: Vivek | I20: =IF(E20>0, "Paid", "Pending")
A21: 19 | B21: Amol Gadge | D21: Flat no 204 | E21: 700 | F21: Online | G21: 06 July 2026 | H21: Vivek | I21: =IF(E21>0, "Paid", "Pending")
A22: 20 | B22: Vishal Bhise | D22: Flat no 205 | E22: 700 | F22: Online | G22: 06 July 2026 | H22: Vivek | I22: =IF(E22>0, "Paid", "Pending")
A23: 21 | B23: Vishnu Wagh | D23: Flat no 206 | E23: 700 | F23: Online | G23: 06 July 2026 | H23: Vivek | I23: =IF(E23>0, "Paid", "Pending")
A24: 22 | B24: Suraj Vadge | D24: Flat no 207 | E24: 700 | F24: Online | G24: 06 July 2026 | H24: Vivek | I24: =IF(E24>0, "Paid", "Pending")
A25: 23 | D25: Flat no 301 | E25: 0 | H25: Vivek | I25: =IF(E25>0, "Paid", "Pending")
A26: 24 | D26: Flat no 302 | E26: 0 | H26: Vivek | I26: =IF(E26>0, "Paid", "Pending")
A27: 25 | B27: Lalitkumar Patil | D27: Flat no 303 | E27: 700 | F27: Online | G27: 13 July 2026 | H27: Vivek | I27: =IF(E27>0, "Paid", "Pending")
A28: 26 | B28: Subhash Chikne | D28: Flat no 304 | E28: 700 | F28: Online | G28: 06 July 2026 | H28: Vivek | I28: =IF(E28>0, "Paid", "Pending")
A29: 27 | B29: Mohan Singh | D29: Flat no 305 | E29: 700 | F29: Online | G29: 09 July 2026 | H29: Vivek | I29: =IF(E29>0, "Paid", "Pending")
A30: 28 | B30: Mohan Singh | D30: Flat no 306 | E30: 700 | F30: Online | G30: 09 July 2026 | H30: Vivek | I30: =IF(E30>0, "Paid", "Pending")
A31: 29 | B31: Mohan Singh | D31: Flat no 307 | E31: 700 | F31: Online | G31: 09 July 2026 | H31: Vivek | I31: =IF(E31>0, "Paid", "Pending")
A32: 30 | B32: Mohan Singh | D32: Flat no 401 | E32: 700 | F32: Online | G32: 09 July 2026 | H32: Vivek | I32: =IF(E32>0, "Paid", "Pending")
A33: 31 | B33: Sourab Patil | D33: Flat no 402 | E33: 0 | H33: Vivek | I33: =IF(E33>0, "Paid", "Pending")
A34: 32 | B34: Oberoi | D34: Flat no 403 | E34: 700 | F34: Online | G34: 07 July 2026 | H34: Vivek | I34: =IF(E34>0, "Paid", "Pending")
A35: 33 | B35: Kiran Yadav | D35: Flat no 404 | E35: 0 | H35: Vivek | I35: =IF(E35>0, "Paid", "Pending")
A36: 34 | B36: Mohan Singh | D36: Flat no 405 | E36: 700 | F36: Online | G36: 09 July 2026 | H36: Vivek | I36: =IF(E36>0, "Paid", "Pending")
A37: 35 | B37: Krushna Roy | D37: Flat no 406 | E37: 700 | F37: Online | G37: 06 July 2026 | H37: Vivek | I37: =IF(E37>0, "Paid", "Pending")
A38: 36 | B38: Suraj Suryavanshi | D38: Flat no 407 | E38: 700 | F38: Online | G38: 06 July 2026 | H38: Vivek | I38: =IF(E38>0, "Paid", "Pending")
A39: 37 | B39: Mhatre | D39: Flat no 501 | E39: 700 | F39: Cash | G39: 09 July 2026 | H39: Vivek | I39: =IF(E39>0, "Paid", "Pending")
A40: 38 | B40: Sourab Patil | D40: Flat no 502 | E40: 0 | H40: Vivek | I40: =IF(E40>0, "Paid", "Pending")
A41: 39 | B41: Baliram Gayvade | D41: Flat no 503 | E41: 700 | F41: Cash | G41: 06 July 2006 | H41: Vivek | I41: =IF(E41>0, "Paid", "Pending")
...

Sheet Expenses
A2: Sr. No. | B2: Month | C2: Description | D2: Amount Paid | E2: Date of Payment
A3: 1 | B3: June | C3: Electricity Bill | D3: 13060
A4: 2 | B4: June | C4: Sevage Cleaning | D4: 4000
A5: 3 | B5: June | C5: D-Mart | D5: 684
A6: 4 | B6: June | C6: Cleaning | D6: 6000
C7: Total Expenses | D7: =SUM(D3:D6)
